<?xml version="1.0"?>
<robot name="ackermann_vehicle"
    xmlns:xacro="http://www.ros.org/wiki/xacro">

    <!-- Materials -->
    <material name="black">
        <color rgba="0.0 0.0 0.0 1.0"/>
    </material>
    <material name="orange">
        <color rgba="1.0 0.5 0.0 1.0"/>
    </material>
    <material name="blue">
        <color rgba="0.0 0.0 0.8 1.0"/>
    </material>

    <!-- Vehicle Dimensions -->
    <xacro:property name="wheel_base_length" value="1.753"/>
    <xacro:property name="wheel_base_width" value="1.245"/>
    <xacro:property name="wheel_diameter" value="0.584"/>
    <xacro:property name="wheel_thickness" value="0.178"/>

    <!-- Macros -->
    <xacro:macro name="wheel" params="name radius width material caster_offset mass">
        <link name="${name}">
            <collision>
                <origin xyz="0 0 0" rpy="0 1.5708 1.5708" />
                <geometry>
                    <cylinder length="${width}" radius="${radius}"/>
                </geometry>
            </collision>
            <visual>
                <origin xyz="0 0 0" rpy="0 1.5708 1.5708" />
                <geometry>
                    <cylinder length="${width}" radius="${radius}"/>
                </geometry>
                <material name="black"/>
            </visual>
            <inertial>
                <origin xyz="0 0 0" rpy="0 1.5708 1.5708" />
                <mass value="0.2"/>
                <!--<cylinder_inertia m="0.2" r="0.3" h="0.1"/> -->
                <xacro:cylinder_inertia m="${mass}" r="${radius}" h="${width}" />
                <!--<inertia ixx="0.23" ixy="0" ixz="0" iyy="0.23" iyz="0" izz="0.4"/>-->
            </inertial>
        </link>
        <gazebo reference="${name}">
            <mu1 value="2.0"/>
            <mu2 value="2.0"/>
            <kp value="10000000.0" />
            <kd value="1.0" />
            <fdir1 value="0 1 0"/>
            <material>${material}</material>
        </gazebo>
    </xacro:macro>

    <xacro:macro name="wheel_steer" params="lr lr_reflect">
        <xacro:wheel name="${lr}" radius="${wheel_diameter/2}" width="${wheel_thickness}" material="Gazebo/Blue" caster_offset="0" mass="6"/>
        <xacro:wheel name="${lr}_assembly" radius="0.1" width="0.001" material="Gazebo/White" caster_offset="-.5" mass="0.5" />

        <joint name="${lr}_hinge" type="revolute">
            <parent link="chassis"/>
            <child link="${lr}_assembly"/>
            <origin xyz="${wheel_base_length/2} ${lr_reflect*(wheel_base_width/2)} ${wheel_diameter/2}" rpy="0 0 0" />
            <axis xyz="0 0 1" rpy="0 0 0" />
            <limit effort="100" velocity="1" lower="-1" upper="1"/>
            <dynamics damping="0.0" friction="0.0"/>
        </joint>
        <joint name="${lr}_rotate" type="continuous">
            <parent link="${lr}_assembly"/>
            <child link="${lr}"/>
            <origin xyz="0.0 ${lr_reflect*(wheel_thickness/2)} 0.0" rpy="0 0 0" />
            <axis xyz="0 1 0" rpy="0 0 0" />
            <limit effort="100" velocity="50"/>
            <dynamics damping="0.0" friction="0.0"/>
        </joint>
        <!-- <transmission name="trans_${lr}_hing">
            <type>transmission_interface/SimpleTransmission</type>
            <joint name="${lr}_hinge">
                <hardwareInterface>EffortJointInterface</hardwareInterface>
            </joint>
            <actuator name="motor_${lr}_front">
                <hardwareInterface>EffortJointInterface</hardwareInterface>
                <mechanicalReduction>1</mechanicalReduction>
            </actuator>
        </transmission>
        <transmission name="trans_${lr}_rotate">
            <type>transmission_interface/SimpleTransmission</type>
            <joint name="${lr}_rotate">
                <hardwareInterface>EffortJointInterface</hardwareInterface>
            </joint>
            <actuator name="motor_${lr}_rotate">
                <hardwareInterface>EffortJointInterface</hardwareInterface>
                <mechanicalReduction>1</mechanicalReduction>
            </actuator>
        </transmission> -->
    </xacro:macro>

    <xacro:macro name="rear_wheel" params="lr lr_reflect">
        <xacro:wheel name="${lr}" radius="${wheel_diameter/2}" width="${wheel_thickness}" material="Gazebo/Blue" caster_offset="0" mass="6" />

        <joint name="${lr}_rotate" type="continuous">
            <parent link="chassis"/>
            <child link="${lr}"/>
            <origin xyz="${-wheel_base_length/2} ${lr_reflect*((wheel_base_width/2)+(wheel_thickness/2))} ${wheel_diameter/2}" rpy="0 0 0" />
            <axis xyz="0 1 0" rpy="0 0 0" />
            <limit effort="0" velocity="0"/>
            <dynamics damping="0.0" friction="0.0"/>
        </joint>

    </xacro:macro>

    <xacro:macro name="box_inertia" params="x y z m">
        <inertia ixx="${m*(y*y+z*z)/12}" ixy = "0" ixz = "0" iyy="${m*(x*x+z*z)/12}" iyz = "0" izz="${m*(x*x+z*z)/12}" />
    </xacro:macro>
    <xacro:macro name="cylinder_inertia" params="m r h">
        <inertia ixx="${(m*((3*r*r)+(h*h)))/12}" ixy = "0" ixz = "0" iyy="${(m*((3*r*r)+(h*h)))/12}" iyz = "0" izz="${(m*r*r)/2}" />
    </xacro:macro>

    <!-- Macros End -->

    <!-- Base link -->
    <link name="base_link">
        <visual>
            <geometry>
                <box size="0.01 0.01 0.01"/>
            </geometry>
        </visual>
    </link>

    <!-- Chassis START-->
    <joint name="base_joint" type="fixed">
        <parent link="base_link"/>
        <child link="chassis"/>
    </joint>

    <link name="chassis">
        <collision>
            <origin xyz="0 0 ${wheel_diameter/2}" rpy="0 0 0"/>
            <geometry>
                <box size="${wheel_base_length} ${wheel_base_width-wheel_thickness} 0.1"/>
            </geometry>
        </collision>
        <visual>
            <origin xyz="0 0 0.3" rpy="0 0 0"/>
            <geometry>
                <box size="${wheel_base_length} ${wheel_base_width-wheel_thickness} 0.1"/>
            </geometry>
            <material name="orange"/>
        </visual>
        <inertial>
            <mass value="1"/>
            <origin xyz="0 0 0.3" rpy="0 0 0"/>
            <xacro:box_inertia x="${wheel_base_length}" y="${wheel_base_width-wheel_thickness}" z=".1" m="1" />
        </inertial>
    </link>
    <!-- Chassis END -->

    <xacro:wheel_steer lr="right_wheel" lr_reflect="-1" />
    <xacro:wheel_steer lr="left_wheel" lr_reflect="1" />
    <xacro:rear_wheel lr="right_wheel_rear" lr_reflect="-1" />
    <xacro:rear_wheel lr="left_wheel_rear" lr_reflect="1" />

    <gazebo>
        <plugin filename="libgz-sim-ackermann-steering-system.so" name="gz::sim::systems::AckermannSteering">
            <left_joint>left_wheel_rear_rotate</left_joint>
            <right_joint>right_wheel_rear_rotate</right_joint>
            <left_steering_joint>left_wheel_hinge</left_steering_joint>
            <right_steering_joint>right_wheel_hinge</right_steering_joint>
            <wheelbase>1.753</wheelbase>
            <track_width>1.245</track_width>
            <wheel_radius>0.292</wheel_radius>
            <min_velocity>-5.0</min_velocity>
            <max_velocity>5.0</max_velocity>
            <min_steering>-0.6</min_steering>
            <max_steering>0.6</max_steering>
            <topic>/cmd_vel</topic>
        </plugin>

        <plugin filename="libgz-sim-odometry-publisher-system.so" name="gz::sim::systems::OdometryPublisher">
            <odom_frame>odom</odom_frame>
            <robot_base_frame>base_link</robot_base_frame>
        </plugin>
        <plugin filename="libgz-sim-joint-state-publisher-system.so" name="gz::sim::systems::JointStatePublisher">
        </plugin>
    </gazebo>

</robot>